Workbook

Sheet RAW_DATA
A1: Customer ID | B1: Customer Name | C1: Last Name | D1: Date of Birth | E1: Sales | F1: Year | G1: Outlet Type | H1: City Type | I1: Category of Goods | J1: Region | K1: Country | L1: Segment | M1: Sales Date | N1: Order ID | O1: Order Date | P1: Ship Date | Q1: Ship Mode | R1: State | S1: Postal Code | T1: Product ID | U1: Sub-Category | V1: Product Name | W1: Quantity | X1: Discount | Y1: Profit
A2: CUST0001 | B2: Mohammed | C2: Nair | D2: 24152 | E2: 648.8 | F2: 2023 | G2: Medium | H2: Tier 2 | I2: Snacks | J2: West | K2: India | L2: Consumer | M2: 45210 | N2: ORD00001 | O2: 45210 | P2: 45211 | Q2: Same Day | R2: Goa | S2: 157174 | T2: PROD0001 | U2: Namkeen | V2: Namkeen - 202 | W2: 4 | X2: 0 | Y2: 67.37
A3: CUST0001 | B3: Mohammed | C3: Nair | D3: 24152 | E3: 782.83 | F3: 2024 | G3: Medium | H3: Tier 2 | I3: Snacks | J3: West | K3: India | L3: Consumer | M3: 45465 | N3: ORD00002 | O3: 45464 | P3: 45465 | Q3: Standard Class | R3: Goa | S3: 561865 | T3: PROD0001 | U3: Namkeen | V3: Namkeen - 814 | W3: 3 | X3: 0.2 | Y3: 154.42
A4: CUST0001 | B4: Mohammed | C4: Nair | D4: 24152 | E4: 2240.62 | F4: 2024 | G4: Medium | H4: Tier 2 | I4: Bakery | J4: West | K4: India | L4: Consumer | M4: 45531 | N4: ORD00003 | O4: 45530 | P4: 45531 | Q4: Same Day | R4: Goa | S4: 705050 | T4: PROD0002 | U4: Bread | V4: Bread - 152 | W4: 5 | X4: 0.05 | Y4: 188.72
A5: CUST0001 | B5: Mohammed | C5: Nair | D5: 24152 | E5: 247.35 | F5: 2025 | G5: Small | H5: Tier 2 | I5: Staples | J5: West | K5: India | L5: Consumer | M5: 45668 | N5: ORD00004 | O5: 45668 | P5: 45669 | Q5: Standard Class | R5: Goa | S5: 735770 | T5: PROD0003 | U5: Pulses | V5: Pulses - 154 | W5: 3 | X5: 0.1 | Y5: 82.8
A6: CUST0001 | B6: Mohammed | C6: Nair | D6: 24152 | E6: 1732.06 | F6: 2025 | G6: Medium | H6: Tier 2 | I6: Snacks | J6: West | K6: India | L6: Consumer | M6: 45708 | N6: ORD00005 | O6: 45705 | P6: 45710 | Q6: Same Day | R6: Goa | S6: 739244 | T6: PROD0004 | U6: Biscuits | V6: Biscuits - 331 | W6: 9 | X6: 0.05 | Y6: 241.11
A7: CUST0002 | B7: Ishaan | C7: Venkatesh | D7: 25422 | E7: 504.27 | F7: 2023 | G7: Medium | H7: Tier 2 | I7: Dairy | J7: East | K7: India | L7: Home Office | M7: 45013 | N7: ORD00006 | O7: 45010 | P7: 45015 | Q7: Same Day | R7: Jharkhand | S7: 342720 | T7: PROD0005 | U7: Yogurt | V7: Yogurt - 277 | W7: 9 | X7: 0 | Y7: 87.01
A8: CUST0002 | B8: Ishaan | C8: Venkatesh | D8: 25422 | E8: 433.36 | F8: 2023 | G8: Small | H8: Tier 2 | I8: Bakery | J8: East | K8: India | L8: Home Office | M8: 45033 | N8: ORD00007 | O8: 45028 | P8: 45033 | Q8: Standard Class | R8: Jharkhand | S8: 220351 | T8: PROD0006 | U8: Cookies | V8: Cookies - 389 | W8: 8 | X8: 0 | Y8: 141.78
A9: CUST0002 | B9: Ishaan | C9: Venkatesh | D9: 25422 | E9: 1094.5 | F9: 2023 | G9: Medium | H9: Tier 2 | I9: Snacks | J9: East | K9: India | L9: Home Office | M9: 45139 | N9: ORD00008 | O9: 45139 | P9: 45140 | Q9: Second Class | R9: Jharkhand | S9: 560485 | T9: PROD0007 | U9: Chips | V9: Chips - 763 | W9: 3 | X9: 0.2 | Y9: 101.43
A10: CUST0002 | B10: Ishaan | C10: Venkatesh | D10: 25422 | E10: 1779.35 | F10: 2023 | G10: Small | H10: Tier 2 | I10: Fruits & Vegetables | J10: East | K10: India | L10: Home Office | M10: 45146 | N10: ORD00009 | O10: 45143 | P10: 45147 | Q10: Same Day | R10: Jharkhand | S10: 553014 | T10: PROD0008 | U10: Onions | V10: Onions - 805 | W10: 5 | X10: 0 | Y10: 356.12
A11: CUST0002 | B11: Ishaan | C11: Venkatesh | D11: 25422 | E11: 162.1 | F11: 2023 | G11: Small | H11: Tier 2 | I11: Staples | J11: East | K11: India | L11: Home Office | M11: 45201 | N11: ORD00010 | O11: 45197 | P11: 45202 | Q11: Second Class | R11: Jharkhand | S11: 704238 | T11: PROD0009 | U11: Wheat Flour | V11: Wheat Flour - 718 | W11: 5 | X11: 0 | Y11: 54.88
A12: CUST0002 | B12: Ishaan | C12: Venkatesh | D12: 25422 | E12: 2994.48 | F12: 2024 | G12: Large | H12: Tier 2 | I12: Fruits & Vegetables | J12: East | K12: India | L12: Home Office | M12: 45570 | N12: ORD00011 | O12: 45567 | P12: 45572 | Q12: Standard Class | R12: Jharkhand | S12: 195674 | T12: PROD0010 | U12: Bananas | V12: Bananas - 581 | W12: 9 | X12: 0 | Y12: 312.76
A13: CUST0002 | B13: Ishaan | C13: Venkatesh | D13: 25422 | E13: 1044.66 | F13: 2024 | G13: Large | H13: Tier 2 | I13: Beverages | J13: East | K13: India | L13: Home Office | M13: 45606 | N13: ORD00012 | O13: 45603 | P13: 45606 | Q13: Standard Class | R13: Jharkhand | S13: 402218 | T13: PROD0011 | U13: Juice | V13: Juice - 518 | W13: 6 | X13: 0 | Y13: 321.04
... A617: CUST0150 | B617: Anjali | C617: Joshi | D617: 35050 | E617: 200.36 | F617: 2024 | G617: Large | H617: Tier 1 | I617: Snacks | J617: West | K617: India | L617: Consumer | M617: 45611 | N617: ORD00616 | O617: 45610 | P617: 45613 | Q617: Second Class | R617: Maharashtra | S617: 842563 | T617: PROD0007 | U617: Chips | V617: Chips - 619 | W617: 2 | X617: 0 | Y617: 62.36

Sheet Clean_Data
A1: Customer ID | B1: Customer Name | C1: Last Name | D1: Date of Birth | E1: Sales | F1: Year | G1: Outlet Type | H1: City Type | I1: Category of Goods | J1: Region | K1: Country | L1: Segment | M1: Sales Date | N1: Order ID | O1: Order Date | P1: Ship Date | Q1: Ship Mode | R1: State | S1: Postal Code | T1: Product ID | U1: Sub-Category | V1: Product Name | W1: Quantity | X1: Discount | Y1: Profit
A2: CUST0001 | B2: Mohammed | C2: Nair | D2: 24152 | E2: 648.8 | F2: 2023 | G2: Medium | H2: Tier 2 | I2: Snacks | J2: West | K2: India | L2: Consumer | M2: 45210 | N2: ORD00001 | O2: 45210 | P2: 45211 | Q2: Same Day | R2: Goa | S2: 157174 | T2: PROD0001 | U2: Namkeen | V2: Namkeen - 202 | W2: 4 | X2: 0 | Y2: 67.37
A3: CUST0001 | B3: Mohammed | C3: Nair | D3: 24152 | E3: 782.83 | F3: 2024 | G3: Medium | H3: Tier 2 | I3: Snacks | J3: West | K3: India | L3: Consumer | M3: 45465 | N3: ORD00002 | O3: 45464 | P3: 45465 | Q3: Standard Class | R3: Goa | S3: 561865 | T3: PROD0001 | U3: Namkeen | V3: Namkeen - 814 | W3: 3 | X3: 0.2 | Y3: 154.42
A4: CUST0001 | B4: Mohammed | C4: Nair | D4: 24152 | E4: 2240.62 | F4: 2024 | G4: Medium | H4: Tier 2 | I4: Bakery | J4: West | K4: India | L4: Consumer | M4: 45531 | N4: ORD00003 | O4: 45530 | P4: 45531 | Q4: Same Day | R4: Goa | S4: 705050 | T4: PROD0002 | U4: Bread | V4: Bread - 152 | W4: 5 | X4: 0.05 | Y4: 188.72
A5: CUST0001 | B5: Mohammed | C5: Nair | D5: 24152 | E5: 247.35 | F5: 2025 | G5: Small | H5: Tier 2 | I5: Staples | J5: West | K5: India | L5: Consumer | M5: 45668 | N5: ORD00004 | O5: 45668 | P5: 45669 | Q5: Standard Class | R5: Goa | S5: 735770 | T5: PROD0003 | U5: Pulses | V5: Pulses - 154 | W5: 3 | X5: 0.1 | Y5: 82.8
A6: CUST0001 | B6: Mohammed | C6: Nair | D6: 24152 | E6: 1732.06 | F6: 2025 | G6: Medium | H6: Tier 2 | I6: Snacks | J6: West | K6: India | L6: Consumer | M6: 45708 | N6: ORD00005 | O6: 45705 | P6: 45710 | Q6: Same Day | R6: Goa | S6: 739244 | T6: PROD0004 | U6: Biscuits | V6: Biscuits - 331 | W6: 9 | X6: 0.05 | Y6: 241.11
A7: CUST0002 | B7: Ishaan | C7: Venkatesh | D7: 25422 | E7: 504.27 | F7: 2023 | G7: Medium | H7: Tier 2 | I7: Dairy | J7: East | K7: India | L7: Home Office | M7: 45013 | N7: ORD00006 | O7: 45010 | P7: 45015 | Q7: Same Day | R7: Jharkhand | S7: 342720 | T7: PROD0005 | U7: Yogurt | V7: Yogurt - 277 | W7: 9 | X7: 0 | Y7: 87.01
A8: CUST0002 | B8: Ishaan | C8: Venkatesh | D8: 25422 | E8: 433.36 | F8: 2023 | G8: Small | H8: Tier 2 | I8: Bakery | J8: East | K8: India | L8: Home Office | M8: 45033 | N8: ORD00007 | O8: 45028 | P8: 45033 | Q8: Standard Class | R8: Jharkhand | S8: 220351 | T8: PROD0006 | U8: Cookies | V8: Cookies - 389 | W8: 8 | X8: 0 | Y8: 141.78
A9: CUST0002 | B9: Ishaan | C9: Venkatesh | D9: 25422 | E9: 1094.5 | F9: 2023 | G9: Medium | H9: Tier 2 | I9: Snacks | J9: East | K9: India | L9: Home Office | M9: 45139 | N9: ORD00008 | O9: 45139 | P9: 45140 | Q9: Second Class | R9: Jharkhand | S9: 560485 | T9: PROD0007 | U9: Chips | V9: Chips - 763 | W9: 3 | X9: 0.2 | Y9: 101.43
A10: CUST0002 | B10: Ishaan | C10: Venkatesh | D10: 25422 | E10: 1779.35 | F10: 2023 | G10: Small | H10: Tier 2 | I10: Fruits & Vegetables | J10: East | K10: India | L10: Home Office | M10: 45146 | N10: ORD00009 | O10: 45143 | P10: 45147 | Q10: Same Day | R10: Jharkhand | S10: 553014 | T10: PROD0008 | U10: Onions | V10: Onions - 805 | W10: 5 | X10: 0 | Y10: 356.12
A11: CUST0002 | B11: Ishaan | C11: Venkatesh | D11: 25422 | E11: 162.1 | F11: 2023 | G11: Small | H11: Tier 2 | I11: Staples | J11: East | K11: India | L11: Home Office | M11: 45201 | N11: ORD00010 | O11: 45197 | P11: 45202 | Q11: Second Class | R11: Jharkhand | S11: 704238 | T11: PROD0009 | U11: Wheat Flour | V11: Wheat Flour - 718 | W11: 5 | X11: 0 | Y11: 54.88
A12: CUST0002 | B12: Ishaan | C12: Venkatesh | D12: 25422 | E12: 2994.48 | F12: 2024 | G12: Large | H12: Tier 2 | I12: Fruits & Vegetables | J12: East | K12: India | L12: Home Office | M12: 45570 | N12: ORD00011 | O12: 45567 | P12: 45572 | Q12: Standard Class | R12: Jharkhand | S12: 195674 | T12: PROD0010 | U12: Bananas | V12: Bananas - 581 | W12: 9 | X12: 0 | Y12: 312.76
A13: CUST0002 | B13: Ishaan | C13: Venkatesh | D13: 25422 | E13: 1044.66 | F13: 2024 | G13: Large | H13: Tier 2 | I13: Beverages | J13: East | K13: India | L13: Home Office | M13: 45606 | N13: ORD00012 | O13: 45603 | P13: 45606 | Q13: Standard Class | R13: Jharkhand | S13: 402218 | T13: PROD0011 | U13: Juice | V13: Juice - 518 | W13: 6 | X13: 0 | Y13: 321.04
... A617: CUST0150 | B617: Anjali | C617: Joshi | D617: 35050 | E617: 200.36 | F617: 2024 | G617: Large | H617: Tier 1 | I617: Snacks | J617: West | K617: India | L617: Consumer | M617: 45611 | N617: ORD00616 | O617: 45610 | P617: 45613 | Q617: Second Class | R617: Maharashtra | S617: 842563 | T617: PROD0007 | U617: Chips | V617: Chips - 619 | W617: 2 | X617: 0 | Y617: 62.36

Sheet Pivottable overview
A1: Category-wise Sales Overview
A3: Category of Goods | B3: Sum of Sales | C3: Count of Order ID | D3: Sum of Profit | E3: Average
A4: Bakery | B4: 142181.06 | C4: 107 | D4: 29303.68 | E4: =AVERAGEIFS(Clean_Data!$X:$X,Clean_Data!$I:$I,A4) -> 0.070560748
A5: Beverages | B5: 145495.57 | C5: 105 | D5: 28571.63 | E5: =AVERAGEIFS(Clean_Data!$X:$X,Clean_Data!$I:$I,A5) -> 0.080952381
A6: Dairy | B6: 126866.26 | C6: 92 | D6: 26224.74 | E6: =AVERAGEIFS(Clean_Data!$X:$X,Clean_Data!$I:$I,A6) -> 0.077173913
A7: Fruits & Vegetables | B7: 131070.93 | C7: 96 | D7: 27564.44 | E7: =AVERAGEIFS(Clean_Data!$X:$X,Clean_Data!$I:$I,A7) -> 0.0765625
A8: Snacks | B8: 137101.08 | C8: 110 | D8: 24539.7 | E8: =AVERAGEIFS(Clean_Data!$X:$X,Clean_Data!$I:$I,A8) -> 0.070454545
A9: Staples | B9: 134498.13 | C9: 106 | D9: 27081.4 | E9: =AVERAGEIFS(Clean_Data!$X:$X,Clean_Data!$I:$I,A9) -> 0.076415094
A10: Grand Total | B10: 817213.03 | C10: 616 | D10: 163285.59 | E10: =AVERAGEIFS(Clean_Data!$X:$X,Clean_Data!$X:$X,">=0") -> 0.075243506
A14: Region-wise Sales Overview
A16: Region | B16: Sum of Sales | C16: Count of Orders | D16: Sum of Profit
A17: Central | B17: 1634426.1 | C17: 1232 | D17: 326571.18
A18: East | B18: 1634426.1 | C18: 1232 | D18: 326571.18
A19: North | B19: 1634426.1 | C19: 1232 | D19: 326571.18
A20: South | B20: 1634426.1 | C20: 1232 | D20: 326571.18
A21: West | B21: 1634426.1 | C21: 1232 | D21: 326571.18
A22: Grand Total | B22: 1634426.1 | C22: 1232 | D22: 326571.18

Sheet RFM
A1: CustomerID | B1: Recency | C1: Frequency | D1: Monetary | E1: R Score | F1: F Score | G1: M Score | H1: RFM Score | I1: Segment
A2: CUST0001 | B2: =TODAY()-_xlfn.MAXIFS(Clean_Data!$O:$O,Clean_Data!$A:$A,A2) -> 611 | C2: =COUNTIF(Clean_Data!$A:$A,A2) -> 5 | D2: =SUMIF(Clean_Data!$A:$A,A2,Clean_Data!$E:$E) -> 5651.66 | E2: =IF(PERCENTRANK($B$2:$B$151,B2)>=0.8,1,IF(PERCENTRANK($B$2:$B$151,B2)>=0.6,2,IF(PERCENTRANK($B$2:$B$151,B2)>=0.4,3,IF(PERCENTRANK($B$2:$B$151,B2)>=0.2,4,5)))) -> 3 | F2: =IF(PERCENTRANK($C$2:$C$151,C2)>=0.8,5,IF(PERCENTRANK($C$2:$C$151,C2)>=0.6,4,IF(PERCENTRANK($C$2:$C$151,C2)>=0.4,3,IF(PERCENTRANK($C$2:$C$151,C2)>=0.2,2,1)))) -> 3 | G2: =IF(PERCENTRANK($D$2:$D$151,D2)>=0.8,5,IF(PERCENTRANK($D$2:$D$151,D2)>=0.6,4,IF(PERCENTRANK($D$2:$D$151,D2)>=0.4,3,IF(PERCENTRANK($D$2:$D$151,D2)>=0.2,2,1)))) -> 3 | H2: =E2+F2+G2 -> 9 | I2: =IF(H2>=13,"Champions",IF(H2>=10,"Loyal Customers",IF(H2>=7,"Potential Loyalist",IF(H2>=4,"At Risk","Lost")))) -> Potential Loyalist
A3: CUST0002 | B3: =TODAY()-_xlfn.MAXIFS(Clean_Data!$O:$O,Clean_Data!$A:$A,A3) -> 608 | C3: =COUNTIF(Clean_Data!$A:$A,A3) -> 8 | D3: =SUMIF(Clean_Data!$A:$A,A3,Clean_Data!$E:$E) -> 8351.21 | E3: =IF(PERCENTRANK($B$2:$B$151,B3)>=0.8,1,IF(PERCENTRANK($B$2:$B$151,B3)>=0.6,2,IF(PERCENTRANK($B$2:$B$151,B3)>=0.4,3,IF(PERCENTRANK($B$2:$B$151,B3)>=0.2,4,5)))) -> 3 | F3: =IF(PERCENTRANK($C$2:$C$151,C3)>=0.8,5,IF(PERCENTRANK($C$2:$C$151,C3)>=0.6,4,IF(PERCENTRANK($C$2:$C$151,C3)>=0.4,3,IF(PERCENTRANK($C$2:$C$151,C3)>=0.2,2,1)))) -> 5 | G3: =IF(PERCENTRANK($D$2:$D$151,D3)>=0.8,5,IF(PERCENTRANK($D$2:$D$151,D3)>=0.6,4,IF(PERCENTRANK($D$2:$D$151,D3)>=0.4,3,IF(PERCENTRANK($D$2:$D$151,D3)>=0.2,2,1)))) -> 5 | H3: =E3+F3+G3 -> 13 | I3: =IF(H3>=13,"Champions",IF(H3>=10,"Loyal Customers",IF(H3>=7,"Potential Loyalist",IF(H3>=4,"At Risk","Lost")))) -> Champions
A4: CUST0003 | B4: =TODAY()-_xlfn.MAXIFS(Clean_Data!$O:$O,Clean_Data!$A:$A,A4) -> 859 | C4: =COUNTIF(Clean_Data!$A:$A,A4) -> 6 | D4: =SUMIF(Clean_Data!$A:$A,A4,Clean_Data!$E:$E) -> 11255.27 | E4: =IF(PERCENTRANK($B$2:$B$151,B4)>=0.8,1,IF(PERCENTRANK($B$2:$B$151,B4)>=0.6,2,IF(PERCENTRANK($B$2:$B$151,B4)>=0.4,3,IF(PERCENTRANK($B$2:$B$151,B4)>=0.2,4,5)))) -> 1 | F4: =IF(PERCENTRANK($C$2:$C$151,C4)>=0.8,5,IF(PERCENTRANK($C$2:$C$151,C4)>=0.6,4,IF(PERCENTRANK($C$2:$C$151,C4)>=0.4,3,IF(PERCENTRANK($C$2:$C$151,C4)>=0.2,2,1)))) -> 4 | G4: =IF(PERCENTRANK($D$2:$D$151,D4)>=0.8,5,IF(PERCENTRANK($D$2:$D$151,D4)>=0.6,4,IF(PERCENTRANK($D$2:$D$151,D4)>=0.4,3,IF(PERCENTRANK($D$2:$D$151,D4)>=0.2,2,1)))) -> 5 | H4: =E4+F4+G4 -> 10 | I4: =IF(H4>=13,"Champions",IF(H4>=10,"Loyal Customers",IF(H4>=7,"Potential Loyalist",IF(H4>=4,"At Risk","Lost")))) -> Loyal Customers
A5: CUST0004 | B5: =TODAY()-_xlfn.MAXIFS(Clean_Data!$O:$O,Clean_Data!$A:$A,A5) -> 627 | C5: =COUNTIF(Clean_Data!$A:$A,A5) -> 5 | D5: =SUMIF(Clean_Data!$A:$A,A5,Clean_Data!$E:$E) -> 6544.88 | E5: =IF(PERCENTRANK($B$2:$B$151,B5)>=0.8,1,IF(PERCENTRANK($B$2:$B$151,B5)>=0.6,2,IF(PERCENTRANK($B$2:$B$151,B5)>=0.4,3,IF(PERCENTRANK($B$2:$B$151,B5)>=0.2,4,5)))) -> 3 | F5: =IF(PERCENTRANK($C$2:$C$151,C5)>=0.8,5,IF(PERCENTRANK($C$2:$C$151,C5)>=0.6,4,IF(PERCENTRANK($C$2:$C$151,C5)>=0.4,3,IF(PERCENTRANK($C$2:$C$151,C5)>=0.2,2,1)))) -> 3 | G5: =IF(PERCENTRANK($D$2:$D$151,D5)>=0.8,5,IF(PERCENTRANK($D$2:$D$151,D5)>=0.6,4,IF(PERCENTRANK($D$2:$D$151,D5)>=0.4,3,IF(PERCENTRANK($D$2:$D$151,D5)>=0.2,2,1)))) -> 4 | H5: =E5+F5+G5 -> 10 | I5: =IF(H5>=13,"Champions",IF(H5>=10,"Loyal Customers",IF(H5>=7,"Potential Loyalist",IF(H5>=4,"At Risk","Lost")))) -> Loyal Customers
A6: CUST0005 | B6: =TODAY()-_xlfn.MAXIFS(Clean_Data!$O:$O,Clean_Data!$A:$A,A6) -> 765 | C6: =COUNTIF(Clean_Data!$A:$A,A6) -> 5 | D6: =SUMIF(Clean_Data!$A:$A,A6,Clean_Data!$E:$E) -> 3377.92 | E6: =IF(PERCENTRANK($B$2:$B$151,B6)>=0.8,1,IF(PERCENTRANK($B$2:$B$151,B6)>=0.6,2,IF(PERCENTRANK($B$2:$B$151,B6)>=0.4,3,IF(PERCENTRANK($B$2:$B$151,B6)>=0.2,4,5)))) -> 2 | F6: =IF(PERCENTRANK($C$2:$C$151,C6)>=0.8,5,IF(PERCENTRANK($C$2:$C$151,C6)>=0.6,4,IF(PERCENTRANK($C$2:$C$151,C6)>=0.4,3,IF(PERCENTRANK($C$2:$C$151,C6)>=0.2,2,1)))) -> 3 | G6: =IF(PERCENTRANK($D$2:$D$151,D6)>=0.8,5,IF(PERCENTRANK($D$2:$D$151,D6)>=0.6,4,IF(PERCENTRANK($D$2:$D$151,D6)>=0.4,3,IF(PERCENTRANK($D$2:$D$151,D6)>=0.2,2,1)))) -> 2 | H6: =E6+F6+G6 -> 7 | I6: =IF(H6>=13,"Champions",IF(H6>=10,"Loyal Customers",IF(H6>=7,"Potential Loyalist",IF(H6>=4,"At Risk","Lost")))) -> Potential Loyalist
A7: CUST0006 | B7: =TODAY()-_xlfn.MAXIFS(Clean_Data!$O:$O,Clean_Data!$A:$A,A7) -> 640 | C7: =COUNTIF(Clean_Data!$A:$A,A7) -> 5 | D7: =SUMIF(Clean_Data!$A:$A,A7,Clean_Data!$E:$E) -> 5757.49 | E7: =IF(PERCENTRANK($B$2:$B$151,B7)>=0.8,1,IF(PERCENTRANK($B$2:$B$151,B7)>=0.6,2,IF(PERCENTRANK($B$2:$B$151,B7)>=0.4,3,IF(PERCENTRANK($B$2:$B$151,B7)>=0.2,4,5)))) -> 3 | F7: =IF(PERCENTRANK($C$2:$C$151,C7)>=0.8,5,IF(PERCENTRANK($C$2:$C$151,C7)>=0.6,4,IF(PERCENTRANK($C$2:$C$151,C7)>=0.4,3,IF(PERCENTRANK($C$2:$C$151,C7)>=0.2,2,1)))) -> 3 | G7: =IF(PERCENTRANK($D$2:$D$151,D7)>=0.8,5,IF(PERCENTRANK($D$2:$D$151,D7)>=0.6,4,IF(PERCENTRANK($D$2:$D$151,D7)>=0.4,3,IF(PERCENTRANK($D$2:$D$151,D7)>=0.2,2,1)))) -> 3 | H7: =E7+F7+G7 -> 9 | I7: =IF(H7>=13,"Champions",IF(H7>=10,"Loyal Customers",IF(H7>=7,"Potential Loyalist",IF(H7>=4,"At Risk","Lost")))) -> Potential Loyalist
A8: CUST0007 | B8: =TODAY()-_xlfn.MAXIFS(Clean_Data!$O:$O,Clean_Data!$A:$A,A8) -> 839 | C8: =COUNTIF(Clean_Data!$A:$A,A8) -> 2 | D8: =SUMIF(Clean_Data!$A:$A,A8,Clean_Data!$E:$E) -> 3559.63 | E8: =IF(PERCENTRANK($B$2:$B$151,B8)>=0.8,1,IF(PERCENTRANK($B$2:$B$151,B8)>=0.6,2,IF(PERCENTRANK($B$2:$B$151,B8)>=0.4,3,IF(PERCENTRANK($B$2:$B$151,B8)>=0.2,4,5)))) -> 1 | F8: =IF(PERCENTRANK($C$2:$C$151,C8)>=0.8,5,IF(PERCENTRANK($C$2:$C$151,C8)>=0.6,4,IF(PERCENTRANK($C$2:$C$151,C8)>=0.4,3,IF(PERCENTRANK($C$2:$C$151,C8)>=0.2,2,1)))) -> 1 | G8: =IF(PERCENTRANK($D$2:$D$151,D8)>=0.8,5,IF(PERCENTRANK($D$2:$D$151,D8)>=0.6,4,IF(PERCENTRANK($D$2:$D$151,D8)>=0.4,3,IF(PERCENTRANK($D$2:$D$151,D8)>=0.2,2,1)))) -> 2 | H8: =E8+F8+G8 -> 4 | I8: =IF(H8>=13,"Champions",IF(H8>=10,"Loyal Customers",IF(H8>=7,"Potential Loyalist",IF(H8>=4,"At Risk","Lost")))) -> At Risk
A9: CUST0008 | B9: =TODAY()-_xlfn.MAXIFS(Clean_Data!$O:$O,Clean_Data!$A:$A,A9) -> 521 | C9: =COUNTIF(Clean_Data!$A:$A,A9) -> 3 | D9: =SUMIF(Clean_Data!$A:$A,A9,Clean_Data!$E:$E) -> 4272.28 | E9: =IF(PERCENTRANK($B$2:$B$151,B9)>=0.8,1,IF(PERCENTRANK($B$2:$B$151,B9)>=0.6,2,IF(PERCENTRANK($B$2:$B$151,B9)>=0.4,3,IF(PERCENTRANK($B$2:$B$151,B9)>=0.2,4,5)))) -> 5 | F9: =IF(PERCENTRANK($C$2:$C$151,C9)>=0.8,5,IF(PERCENTRANK($C$2:$C$151,C9)>=0.6,4,IF(PERCENTRANK($C$2:$C$151,C9)>=0.4,3,IF(PERCENTRANK($C$2:$C$151,C9)>=0.2,2,1)))) -> 2 | G9: =IF(PERCENTRANK($D$2:$D$151,D9)>=0.8,5,IF(PERCENTRANK($D$2:$D$151,D9)>=0.6,4,IF(PERCENTRANK($D$2:$D$151,D9)>=0.4,3,IF(PERCENTRANK($D$2:$D$151,D9)>=0.2,2,1)))) -> 2 | H9: =E9+F9+G9 -> 9 | I9: =IF(H9>=13,"Champions",IF(H9>=10,"Loyal Customers",IF(H9>=7,"Potential Loyalist",IF(H9>=4,"At Risk","Lost")))) -> Potential Loyalist
A10: CUST0009 | B10: =TODAY()-_xlfn.MAXIFS(Clean_Data!$O:$O,Clean_Data!$A:$A,A10) -> 787 | C10: =COUNTIF(Clean_Data!$A:$A,A10) -> 5 | D10: =SUMIF(Clean_Data!$A:$A,A10,Clean_Data!$E:$E) -> 5963.86 | E10: =IF(PERCENTRANK($B$2:$B$151,B10)>=0.8,1,IF(PERCENTRANK($B$2:$B$151,B10)>=0.6,2,IF(PERCENTRANK($B$2:$B$151,B10)>=0.4,3,IF(PERCENTRANK($B$2:$B$151,B10)>=0.2,4,5)))) -> 2 | F10: =IF(PERCENTRANK($C$2:$C$151,C10)>=0.8,5,IF(PERCENTRANK($C$2:$C$151,C10)>=0.6,4,IF(PERCENTRANK($C$2:$C$151,C10)>=0.4,3,IF(PERCENTRANK($C$2:$C$151,C10)>=0.2,2,1)))) -> 3 | G10: =IF(PERCENTRANK($D$2:$D$151,D10)>=0.8,5,IF(PERCENTRANK($D$2:$D$151,D10)>=0.6,4,IF(PERCENTRANK($D$2:$D$151,D10)>=0.4,3,IF(PERCENTRANK($D$2:$D$151,D10)>=0.2,2,1)))) -> 3 | H10: =E10+F10+G10 -> 8 | I10: =IF(H10>=13,"Champions",IF(H10>=10,"Loyal Customers",IF(H10>=7,"Potential Loyalist",IF(H10>=4,"At Risk","Lost")))) -> Potential Loyalist
A11: CUST0010 | B11: =TODAY()-_xlfn.MAXIFS(Clean_Data!$O:$O,Clean_Data!$A:$A,A11) -> 542 | C11: =COUNTIF(Clean_Data!$A:$A,A11) -> 6 | D11: =SUMIF(Clean_Data!$A:$A,A11,Clean_Data!$E:$E) -> 11387.96 | E11: =IF(PERCENTRANK($B$2:$B$151,B11)>=0.8,1,IF(PERCENTRANK($B$2:$B$151,B11)>=0.6,2,IF(PERCENTRANK($B$2:$B$151,B11)>=0.4,3,IF(PERCENTRANK($B$2:$B$151,B11)>=0.2,4,5)))) -> 4 | F11: =IF(PERCENTRANK($C$2:$C$151,C11)>=0.8,5,IF(PERCENTRANK($C$2:$C$151,C11)>=0.6,4,IF(PERCENTRANK($C$2:$C$151,C11)>=0.4,3,IF(PERCENTRANK($C$2:$C$151,C11)>=0.2,2,1)))) -> 4 | G11: =IF(PERCENTRANK($D$2:$D$151,D11)>=0.8,5,IF(PERCENTRANK($D$2:$D$151,D11)>=0.6,4,IF(PERCENTRANK($D$2:$D$151,D11)>=0.4,3,IF(PERCENTRANK($D$2:$D$151,D11)>=0.2,2,1)))) -> 5 | H11: =E11+F11+G11 -> 13 | I11: =IF(H11>=13,"Champions",IF(H11>=10,"Loyal Customers",IF(H11>=7,"Potential Loyalist",IF(H11>=4,"At Risk","Lost")))) -> Champions
A12: CUST0011 | B12: =TODAY()-_xlfn.MAXIFS(Clean_Data!$O:$O,Clean_Data!$A:$A,A12) -> 741 | C12: =COUNTIF(Clean_Data!$A:$A,A12) -> 2 | D12: =SUMIF(Clean_Data!$A:$A,A12,Clean_Data!$E:$E) -> 1920.29 | E12: =IF(PERCENTRANK($B$2:$B$151,B12)>=0.8,1,IF(PERCENTRANK($B$2:$B$151,B12)>=0.6,2,IF(PERCENTRANK($B$2:$B$151,B12)>=0.4,3,IF(PERCENTRANK($B$2:$B$151,B12)>=0.2,4,5)))) -> 2 | F12: =IF(PERCENTRANK($C$2:$C$151,C12)>=0.8,5,IF(PERCENTRANK($C$2:$C$151,C12)>=0.6,4,IF(PERCENTRANK($C$2:$C$151,C12)>=0.4,3,IF(PERCENTRANK($C$2:$C$151,C12)>=0.2,2,1)))) -> 1 | G12: =IF(PERCENTRANK($D$2:$D$151,D12)>=0.8,5,IF(PERCENTRANK($D$2:$D$151,D12)>=0.6,4,IF(PERCENTRANK($D$2:$D$151,D12)>=0.4,3,IF(PERCENTRANK($D$2:$D$151,D12)>=0.2,2,1)))) -> 1 | H12: =E12+F12+G12 -> 4 | I12: =IF(H12>=13,"Champions",IF(H12>=10,"Loyal Customers",IF(H12>=7,"Potential Loyalist",IF(H12>=4,"At Risk","Lost")))) -> At Risk
A13: CUST0012 | B13: =TODAY()-_xlfn.MAXIFS(Clean_Data!$O:$O,Clean_Data!$A:$A,A13) -> 949 | C13: =COUNTIF(Clean_Data!$A:$A,A13) -> 5 | D13: =SUMIF(Clean_Data!$A:$A,A13,Clean_Data!$E:$E) -> 7823.82 | E13: =IF(PERCENTRANK($B$2:$B$151,B13)>=0.8,1,IF(PERCENTRANK($B$2:$B$151,B13)>=0.6,2,IF(PERCENTRANK($B$2:$B$151,B13)>=0.4,3,IF(PERCENTRANK($B$2:$B$151,B13)>=0.2,4,5)))) -> 1 | F13: =IF(PERCENTRANK($C$2:$C$151,C13)>=0.8,5,IF(PERCENTRANK($C$2:$C$151,C13)>=0.6,4,IF(PERCENTRANK($C$2:$C$151,C13)>=0.4,3,IF(PERCENTRANK($C$2:$C$151,C13)>=0.2,2,1)))) -> 3 | G13: =IF(PERCENTRANK($D$2:$D$151,D13)>=0.8,5,IF(PERCENTRANK($D$2:$D$151,D13)>=0.6,4,IF(PERCENTRANK($D$2:$D$151,D13)>=0.4,3,IF(PERCENTRANK($D$2:$D$151,D13)>=0.2,2,1)))) -> 5 | H13: =E13+F13+G13 -> 9 | I13: =IF(H13>=13,"Champions",IF(H13>=10,"Loyal Customers",IF(H13>=7,"Potential Loyalist",IF(H13>=4,"At Risk","Lost")))) -> Potential Loyalist
... A151: CUST0150 | B151: =TODAY()-_xlfn.MAXIFS(Clean_Data!$O:$O,Clean_Data!$A:$A,A151) -> 706 | C151: =COUNTIF(Clean_Data!$A:$A,A151) -> 5 | D151: =SUMIF(Clean_Data!$A:$A,A151,Clean_Data!$E:$E) -> 5423.24 | E151: =IF(PERCENTRANK($B$2:$B$151,B151)>=0.8,1,IF(PERCENTRANK($B$2:$B$151,B151)>=0.6,2,IF(PERCENTRANK($B$2:$B$151,B151)>=0.4,3,IF(PERCENTRANK($B$2:$B$151,B151)>=0.2,4,5)))) -> 2 | F151: =IF(PERCENTRANK($C$2:$C$151,C151)>=0.8,5,IF(PERCENTRANK($C$2:$C$151,C151)>=0.6,4,IF(PERCENTRANK($C$2:$C$151,C151)>=0.4,3,IF(PERCENTRANK($C$2:$C$151,C151)>=0.2,2,1)))) -> 3 | G151: =IF(PERCENTRANK($D$2:$D$151,D151)>=0.8,5,IF(PERCENTRANK($D$2:$D$151,D151)>=0.6,4,IF(PERCENTRANK($D$2:$D$151,D151)>=0.4,3,IF(PERCENTRANK($D$2:$D$151,D151)>=0.2,2,1)))) -> 3 | H151: =E151+F151+G151 -> 8 | I151: =IF(H151>=13,"Champions",IF(H151>=10,"Loyal Customers",IF(H151>=7,"Potential Loyalist",IF(H151>=4,"At Risk","Lost")))) -> Potential Loyalist

Sheet Data_Analysis
A2: RFM Segment Destribution | D2: Monthly Sales Trend | G2: Sales by Category | J2: Top Customer by Monetary Value
A3: Row Labels | B3: Count of Segment | D3: Row Labels | E3: Sum of Sales | G3: Row Labels | H3: Sum of Sales | J3: Row Labels | K3: Sum of Monetary
A4: At Risk | B4: 35 | D4: 2023 | E4: 355077.78 | G4: Bakery | H4: 142181.06 | J4: CUST0001 | K4: 5651.66
A5: Champions | B5: 21 | D5: Jan | E5: 17102.09 | G5: Beverages | H5: 145495.57 | J5: CUST0002 | K5: 8351.21
A6: Lost | B6: 9 | D6: Feb | E6: 31424.77 | G6: Dairy | H6: 126866.26 | J6: CUST0003 | K6: 11255.27
A7: Loyal Customers | B7: 49 | D7: Mar | E7: 30456.43 | G7: Fruits & Vegetables | H7: 131070.93 | J7: CUST0004 | K7: 6544.88
A8: Potential Loyalist | B8: 36 | D8: Apr | E8: 41322.42 | G8: Snacks | H8: 137101.08 | J8: CUST0005 | K8: 3377.92
A9: (blank) | D9: May | E9: 32680.8 | G9: Staples | H9: 134498.13 | J9: CUST0006 | K9: 5757.49
A10: Grand Total | B10: 150 | D10: Jun | E10: 30455.66 | G10: Grand Total | H10: 817213.03 | J10: CUST0007 | K10: 3559.63
D11: Jul | E11: 36950.62 | J11: CUST0008 | K11: 4272.28
A12: Customer Count by Segment | D12: Aug | E12: 27418.5 | J12: CUST0009 | K12: 5963.86
A13: Row Labels | B13: Count of CustomerID | D13: Sep | E13: 25574.62 | J13: CUST0010 | K13: 11387.96
A14: At Risk | B14: 35 | D14: Oct | E14: 35858.56 | J14: CUST0011 | K14: 1920.29
A15: Champions | B15: 21 | D15: Nov | E15: 24667.52 | J15: CUST0012 | K15: 7823.82
A16: Lost | B16: 9 | D16: Dec | E16: 21165.79 | J16: CUST0013 | K16: 4971.73
A17: Loyal Customers | B17: 49 | D17: 2024 | E17: 306575.96 | J17: CUST0014 | K17: 5685.45
A18: Potential Loyalist | B18: 36 | D18: Jan | E18: 20383.72 | J18: CUST0015 | K18: 4357.67
A19: Grand Total | B19: 150 | D19: Feb | E19: 19772.48 | J19: CUST0016 | K19: 3697.85
D20: Mar | E20: 22459.45 | J20: CUST0017 | K20: 6907.66
D21: Apr | E21: 36783.18 | J21: CUST0018 | K21: 6191.28
A22: Monetary Value by RFM Segment | D22: May | E22: 30174.36 | J22: CUST0019 | K22: 3644.8
D23: Jun | E23: 37113.63 | J23: CUST0020 | K23: 9432.81
A24: Row Labels | B24: Sum of Monetary | D24: Jul | E24: 23176.8 | J24: CUST0021 | K24: 1059.41
A25: At Risk | B25: 91067.87 | D25: Aug | E25: 32941.22 | J25: CUST0022 | K25: 7912.86
A26: Champions | B26: 198368.57 | D26: Sep | E26: 18412.2 | J26: CUST0023 | K26: 7485.25
A27: Lost | B27: 12753.87 | D27: Oct | E27: 19649.19 | J27: CUST0024 | K27: 4336.45
A28: Loyal Customers | B28: 355995.99 | D28: Nov | E28: 33377.33 | J28: CUST0025 | K28: 6858.87
A29: Potential Loyalist | B29: 159026.73 | D29: Dec | E29: 12332.4 | J29: CUST0026 | K29: 1434.12
A30: Grand Total | B30: 817213.03 | D30: 2025 | E30: 155559.29 | J30: CUST0027 | K30: 7603.57
D31: Jan | E31: 28735.56 | J31: CUST0028 | K31: 4506.84
D32: Feb | E32: 27269.85 | J32: CUST0029 | K32: 6224.47
D33: Mar | E33: 11233.06 | J33: CUST0030 | K33: 14930.06
D34: Apr | E34: 27337.04 | J34: CUST0031 | K34: 13630.14
D35: May | E35: 30727.73 | J35: CUST0032 | K35: 2025.93
D36: Jun | E36: 28749.31 | J36: CUST0033 | K36: 8206.35
D37: Jul | E37: 1506.74 | J37: CUST0034 | K37: 10559.57
D38: Grand Total | E38: 817213.03 | J38: CUST0035 | K38: 7405.84
J39: CUST0036 | K39: 2419.07
J40: CUST0037 | K40: 6728.83
J41: CUST0038 | K41: 2475.85
...

Sheet Dashboard
